---
layout: post
title: "异常"
data: 2017-12-26
description: "异常"
tag: JavaSE
---


### 异常 ###

 - 异常概念 
    java异常是以异常类的形式对异常进行封装，通过异常处理机制对程序运行时发生的各种问题进行处理，java提供了大量的异常类。他们都继承自java.lang.Throwable类
    ![][1]
    
    Throwable有两个直接的子类Error和Expection，其中Error代表错误类，Exception代表异常类。
    - Error：代表错误类，它表示java运行时产生的系统内部错误或资源耗尽错误，是比较严重的，不能仅靠修改程序本身来恢复命令的执行，如：编译一个不存在的主类，会抛出无法加载主类的错误。
    - Exception：异常类，表示程序本身可以处理的错误，在开发java程序进行的异常处理都是针对Exception及其子类。在Exception的众多子类中，有一个特殊的类RuntimeException，该类及其子类都表示运行时异常，除此之外，Exception的其他子类都表示编译时异常。
    以下是Throwable的常用方法：

    > String getMessage()，返回此Throwable的详细消息字符串
    
    > void printStackTrace()，将此Throwable及其追踪输出至标准错误流
    
    > void printfStackTrace(PrintStream s)，将此Throwable及其追踪输出至指定流。

 - 异常处理
    - try...catch

    由于程序发生了异常会立即停止无法继续执行，为了解决这样的问题，java提供了一种解决的机制，异常捕获，用try catch 语句，格式如下：
    
        try{
            //程序代码块，可能发生异常的语句
        }catch(ExceptionType e){
            //对ExceptionType的处理
        }
    当try代码块中的程序发生了异常，系统会将这个异常心系封装成一个异常对象，并将这个异常传递给catch代码块，catch代码块需要一个参数指明它所能够接受的异常类型，这个参数类型必须是Exception及其子类。


        public class Main{
	        public static int divide(int x, int y){
		        return x/y;
	        }
	        public static void main(String[] args){
		        try{
		            int result = divide(1, 0);
			        System.out.println(result);	
		        }catch(Exception e){
			        System.out.println("捕获的异常信息为：" + e.getMessage());
		        }
		        System.out.println("程序向下执行");
	        }
        }
            
        //结果
        捕获的异常信息为：/ by zero
        程序向下执行
            
            
            

    - finally

        当我们希望无论有没有异常，都执行一些代码，我们就可以通过finally来执行。
    


            public class Main{
	            public static int divide(int x, int y){
		            return x/y;
	            }
	            public static void main(String[] args){
		            try{
		                int result = divide(1, 0);
			            System.out.println(result);	
		            }catch(Exception e){
			            System.out.println("捕获的异常信息为：" + e.getMessage());
			            return ;
		            }finally{
			            System.out.println("进入finally代码块...");
		            }
		            System.out.println("程序向下执行");
	            }
            }
    
            //结果
            捕获的异常信息为：/ by zero
            进入finally代码块...
    


        执行完catch已经return ，但是还是执行了finally内的代码。不管发生什么，即使前面有return，finally中的代码还是会执行，正是因为这种原因，经常利用finally来释放系统资源。但是如果try...catch中执行了System.exit(0)；finally不会执行。




            public class Main{
	            public static int divide(int x, int y){
		            return x/y;
	            }
	            public static void main(String[] args){
		            try{
		                int result = divide(1, 0 );
			            System.out.println(result);	
		            }catch(Exception e){
			            System.out.println("捕获的异常信息为：" + e.getMessage());
			            System.exit(0);
		            }finally{
			            System.out.println("进入finally代码块...");
		            }
		            System.out.println("程序向下执行");
	            }
            }

            //结果
            捕获的异常信息为：/ by zero
    
    


    - throws

        当自己写的代码和别人的合并时，被调用的别人的代码可能会也有异常，但难以区分，由此有了throws，可以定义在函数后抛出异常。这样调用者在调用这个函数时，就明显知道该方法有异常，必须在程序中进行处理，否则编译无法通过。格式如下：
    
        修饰符 返回值类型 方法名（参数类型 参数名，参数类型 参数名）throws Excception1,Exception2{}
    



            public class Main{
	            public static int divide(int x, int y)throws Exception{
		            return x/y;
	            }
	            public static void main(String[] args){
		            try{
		                int result = divide(1, 0);
			            System.out.println(result);	//11行
		            }catch(Exception e){
			            e.printStackTrace();
		            }finally{
			            //...
		            }
		            System.out.println("程序向下执行");
	            }
            }
    
            //结果
            java.lang.ArithmeticException: / by zero程序向下执行

	        at class_1.Main.divide(Main.java:5)
	        at class_1.Main.main(Main.java:9)


       当程序内部无法进行异常的处理时，可以再次抛出，本程序即main函数后面throws。
       


----------


- 异常分类
    在实际开发过程中，经常会在程序编译时残生一些异常，而且这些异常必须经过处理，这种异常通常被称为编译时异常，也称checked异常。还有另外一种是在程序运行时产生的，这种异常即使不编写异常处理代码，也可以通过编译，称为运行时异常。
    - 编译时异常
        在java中，除了RunTimeException类是运行时异常外，其余Exception的子类都是编译时异常。编译时异常特点是java编译时会进行检查，如果出现异常就必须进行处理，否则无法通过编译。
        处理编译时一般有以下的两种方式：
        使用try...catch语句对异常进行处理。
        使用throws关键字抛出声明异常，调用者对其处理。
        
    - 运行时异常
        一般是由程序的逻辑错误引起的，运行时无法恢复，比如数组下标越界。
- 自定义异常 
    JDK定义了很多的异常代码类，但是也有许多特殊情况，如前面程序中不允许除0。为了解决这类问题，java允许用户自定义异常。但自定义的异常类，必须继承自Exception或其子类。
    在实际开发中，如果不是特殊需要，自定义异常类只需继承Exception类，在构造函数中继承Exception的super()方法即可。
    



        class DivideByMinusException extends Exception{
    	    public DivideByMinusException(){
		        super();   //调用Exception的无参构造函数
	        }
	        public DivideByMinusException(String message){
		        super(message);   //调用Exception的有参构造函数
	        }
        }
    


    自定义异常后，该怎么使用呢？这就用到了throw关键字，throw用于在方法中声明抛出异常的实例对象，语法格式为：
> throw Exception 异常对象


        public static int divide(int x, int y){
		    if(y == 0){
			    throw new DivideByMinusException("被除数为0");
		    }else{
			    return x/y;
		    }
	    }
    


    尽管调用了自定义的异常类，但是只是调用而没有进行异常的处理，如果不从此处处理这个异常就可以把这个异常抛出，让调用者处理。代码修改为：



        public class Main{
	        public static int divide(int x, int y)throws DivideByMinusException{
		        if(y == 0){
		    	    throw new DivideByMinusException("被除数为0");
		        }else{
			        return x/y;
		        }
	        }
	        public static void main(String[] args){
		        try{
			        int result = divide(4,0);
			        System.out.println(result);
		        }catch(Exception e){
			        System.out.println(e.getMessage());
		        }finally{
			        //...
		        }
		        System.out.println("程序向下执行");
	        }
        }

        //结果为
        被除数为0
        程序向下执行
    
----------


 


  [1]: /images/posts/JavaSE6/result1.png




